# Bug Report: UnboundLocalError in enhanced_response_validator.py

## Summary
There is a critical bug in `src/testpilot/core/enhanced_response_validator.py` that causes an `UnboundLocalError` when `partial_dict_match` is set to `False` in the configuration.

## Location
**File**: `src/testpilot/core/enhanced_response_validator.py`
**Lines**: 286-308

## Bug Description
When `partial_dict_match=False`, the variable `dict_match_result` is never defined, but the code still tries to reference it in the logging statement.

## Current Buggy Code
```python
# Line 286-306
if (
    partial_dict_match  # When this is False...
    and expected is not None
    and actual_clean is not None
):
    dict_match_result = compare_json_objects(...)  # This never executes
    # ... dict_match logic

logger.info(
    f"Response payload matches actual with {dict_match_result['match_percentage']}% confidence."
)  # But this always tries to access dict_match_result - CRASH!
```

## Error Message
```
UnboundLocalError: cannot access local variable 'dict_match_result' where it is not associated with a value
```

## Test Case That Reproduces Bug
```python
def test_bug_reproduction():
    result = validate_response_enhanced(
        pattern_match=None,
        response_headers=None,
        response_body={"name": "John", "age": 30},
        response_payload={"name": "John", "age": 30},
        logger=logger,
        config={"partial_dict_match": False}  # This triggers the bug
    )
```

## Suggested Fix
```python
# Around line 286-308
elif isinstance(response_payload, dict):
    logger.debug("Performing dict comparison using response_payload as expected.")
    expected = _remove_ignored_fields(response_payload, ignore_fields)
    actual_clean = _remove_ignored_fields(actual, ignore_fields)

    if partial_dict_match and expected is not None and actual_clean is not None:
        dict_match_result = compare_json_objects(
            expected,
            actual_clean,
            "structure_and_values",
            ignore_array_order=ignore_array_order,
        )
        differences = (
            dict_match_result["missing_details"]
            if dict_match_result["match_percentage"] <= 50
            else None
        )
        dict_match = dict_match_result["match_percentage"] > 50

        logger.info(
            f"Response payload matches actual with {dict_match_result['match_percentage']}% confidence."
        )
    else:
        # Handle the case when partial_dict_match=False
        dict_match = _is_subset_dict(expected, actual_clean, partial=False)
        differences = None if dict_match else _dict_diff(expected, actual_clean)
        logger.info("Response payload comparison completed with strict matching.")

    logger.debug(f"Dict comparison result: {dict_match}, differences: {differences}")
```

## Impact
- **Severity**: High - Causes application crash
- **Affected Functionality**: All validation when `partial_dict_match=False`
- **Workaround**: Always use `partial_dict_match=True` (default) or avoid setting config

## Test Coverage
The bug is now documented in the test suite:
- `test_validate_with_config_partial_false_bug()` - Reproduces and documents the bug
- `test_validate_with_partial_matching_enabled_default()` - Tests working functionality
